Workbook

Sheet Start Here
A1: FORGED — THE 4-DAY POWERBUILDER
A2: Strength you keep. Muscle you build. Training you actually enjoy. | 8-week repeatable cycle
B4: YOUR CURRENT MAXES (edit these — every working weight in the program updates automatically)
B6: Lift | C6: 1RM (lbs)
B7: Squat | C7: 445
B8: Bench Press | C8: 275
B9: Deadlift | C9: 515
B11: HOW TO USE THIS TRACKER
B12: 1. Each Week tab is one full training week: Tuesday, Thursday, Saturday, Sunday.
B13: 2. Main lifts (squat, bench, deadlift + variations) have one row PER SET — log weight, reps, RPE, and a note for every set.
B14: 3. Target Weight is calculated from your maxes above and rounded to 5 lbs. RPE is the boss: if the % feels heavier than the target RPE, cut weight. If it's way easier, you may add 2.5-5%.
B15: 4. Accessories use double progression: work within the rep range, and when you hit the top of the range on ALL sets, add weight next week. 'Your pick' means choose the load that hits the target RPE.
B16: 5. Use the Set Notes column relentlessly — bar speed, pump quality, tweaks, cues that clicked. Next cycle, those notes are gold.
B17: 6. Weeks 4 and 8 are deloads (tan rows). Do them. You grow when you recover.
B18: 7. After Week 8: take Week 7's AMRAP/heavy single, estimate new maxes (see guide), update the table above, and run it again.
B19: 8. Read PROGRAM-GUIDE.md — it explains every exercise, every choice, and every specialty technique in this program.
B22: RPE CHEAT SHEET
B23: RPE | C23: Meaning
B24: 6 | C24: Comfortable — 4+ reps left in the tank. Speed work / deloads.
B25: 7 | C25: Solid effort — 3 clean reps left. Bar moves fast.
B26: 7.5 | C26: 2-3 reps left.
B27: 8 | C27: 2 reps left. Bar slows a touch. The bread-and-butter training zone.
B28: 8.5 | C28: 1-2 reps left.
B29: 9 | C29: 1 rep left. Heavy. Only where programmed.
B30: 10 | C30: Nothing left. NOT used in this program — save it for a platform that isn't coming. Build, don't test.
B33: 8-WEEK MAP
B34: Week | C34: Block | D34: Main-lift focus
B35: 1-3 | C35: Volume & Movement Quality | D35: Sets of 5-6 @ 70-75%, RPE 7→8. Build work capacity and technique.
B36: 4 | C36: DELOAD | D36: 60% for easy 5s. Recover and grow.
B37: 5-7 | C37: Strength Expression | D37: Sets of 3-4 @ 77.5-82.5%, RPE 7.5→8.5. Week 7: optional AMRAP / heavy single.
B38: 8 | C38: DELOAD | D38: 65% for easy 3s. Reset, update maxes, run it back.

Sheet Week 1
A1: FORGED 4-DAY POWERBUILDER — WEEK 1 | BLOCK 1: VOLUME & MOVEMENT QUALITY
A2: TUESDAY — LOWER A: SQUAT STRENGTH + POSTERIOR CHAIN (target: ≤85 min)
A3: Exercise | B3: Set | C3: Target Reps | D3: %1RM | E3: Target Weight | F3: Target RPE | G3: Rest | H3: Coaching Cues / Special Instructions | I3: Actual Weight | J3: Actual Reps | K3: Actual RPE | L3: Set Notes (how it felt, bar speed, pump, tweaks)
A4: Competition Squat | B4: 1 | C4: 6 | D4: 70% | E4: =MROUND('Start Here'!$C$7*0.7,5) | F4: 7 | G4: 3-4 min | H4: Full comp setup every set: same walkout, same bracing. Big 360° breath, spread the floor, drive up through mid-foot. Treat every rep like a platform rep.
B5: 2 | C5: 6 | D5: 70% | E5: =MROUND('Start Here'!$C$7*0.7,5) | F5: 7 | G5: 3-4 min
B6: 3 | C6: 6 | D6: 70% | E6: =MROUND('Start Here'!$C$7*0.7,5) | F6: 7 | G6: 3-4 min
B7: 4 | C7: 6 | D7: 70% | E7: =MROUND('Start Here'!$C$7*0.7,5) | F7: 7 | G7: 3-4 min
A8: Romanian Deadlift | B8: 3 | C8: 8-10 | D8: — | E8: Your pick | F8: 7-8 | G8: 2-3 min | H8: Soft knees, push hips back until hamstrings scream, bar drags the thighs. Start ~185-225 and add when all sets hit 10. Feel the stretch — that's the growth signal.
A9: Leg Press (feet low & narrow) | B9: 3 | C9: 10-12 | D9: — | E9: Your pick | F9: 8 | G9: 2 min | H9: Quad-bias stance. Full depth without butt tucking, 2-sec lowering. Drive knees over toes. Don't chase plates — chase the quad burn.
A10: Seated Leg Curl | B10: 3 | C10: 12-15 | D10: — | E10: Your pick | F10: 8-9 | G10: 90 sec | H10: Lean torso forward slightly for a longer hamstring stretch. Squeeze 1 sec at full flexion, 3-sec lowering.
A11: Standing Calf Raise | B11: 3 | C11: 10-12 | D11: — | E11: Your pick | F11: 8-9 | G11: 90 sec | H11: Full stretch at the bottom for a 2-count, drive through the big toe, pause at the top. No bouncing.
A12: Cable Crunch | B12: 3 | C12: 12-15 | D12: — | E12: Your pick | F12: 8 | G12: 60-90 sec | H12: Flex the spine — ribs to hips, don't just bow at the waist. Strong abs = strong squat brace.
A14: THURSDAY — UPPER A: BENCH STRENGTH + BACK (target: ≤85 min)
A15: Exercise | B15: Set | C15: Target Reps | D15: %1RM | E15: Target Weight | F15: Target RPE | G15: Rest | H15: Coaching Cues / Special Instructions | I15: Actual Weight | J15: Actual Reps | K15: Actual RPE | L15: Set Notes (how it felt, bar speed, pump, tweaks)
A16: Competition Bench | B16: 1 | C16: 6 | D16: 70% | E16: =MROUND('Start Here'!$C$8*0.7,5) | F16: 7 | G16: 3-4 min | H16: Comp pause on every rep this day. Set your arch, pull the bar apart, tuck elbows ~45°, press back over your face. Leg drive on.
B17: 2 | C17: 6 | D17: 70% | E17: =MROUND('Start Here'!$C$8*0.7,5) | F17: 7 | G17: 3-4 min
B18: 3 | C18: 6 | D18: 70% | E18: =MROUND('Start Here'!$C$8*0.7,5) | F18: 7 | G18: 3-4 min
B19: 4 | C19: 6 | D19: 70% | E19: =MROUND('Start Here'!$C$8*0.7,5) | F19: 7 | G19: 3-4 min
A20: Weighted Pull-Up | B20: 4 | C20: 6-8 | D20: — | E20: Your pick | F20: 8 | G20: 2-3 min | H20: Add weight when you own 4x8 at bodyweight+. Dead hang start, drive elbows to hips, chest to bar. Lats build your bench arch and your V-taper.
A21: Seated DB Shoulder Press | B21: 3 | C21: 8-10 | D21: — | E21: Your pick | F21: 8 | G21: 2 min | H21: Slight back support, press up-and-in, stop just short of lockout to keep tension on delts. Start ~55-65s.
A22: Chest-Supported Row | B22: 3 | C22: 10-12 | D22: — | E22: Your pick | F22: 8 | G22: 90 sec | H22: Chest glued to pad — no cheating with body English. Pull to lower ribs, squeeze the shoulder blades for 1 sec.
A23: SUPERSET: EZ-Bar Curl + Overhead Cable Extension | B23: 3 | C23: 10-12 each | D23: — | E23: Your pick | F23: 8 | G23: 90 sec after pair | H23: Curls: elbows pinned, no swing. Overhead extensions: full stretch behind head — long-head triceps grow from the stretch. Alternate exercises, rest after both.
A24: Face Pull | B24: 3 | C24: 15-20 | D24: — | E24: Your pick | F24: 8 | G24: 60 sec | H24: Rope to forehead, thumbs back, external rotate at the end. Shoulder insurance — never skip these.
A26: SATURDAY — LOWER B: DEADLIFT + ATHLETIC LOWER (long session — take your time)
A27: Exercise | B27: Set | C27: Target Reps | D27: %1RM | E27: Target Weight | F27: Target RPE | G27: Rest | H27: Coaching Cues / Special Instructions | I27: Actual Weight | J27: Actual Reps | K27: Actual RPE | L27: Set Notes (how it felt, bar speed, pump, tweaks)
A28: Deadlift | B28: 1 | C28: 5 | D28: 70% | E28: =MROUND('Start Here'!$C$9*0.7,5) | F28: 7 | G28: 3-4 min | H28: Wedge hard, pull the slack out until the bar clicks, push the floor away. Hips and shoulders rise together. Reset every rep — no touch-and-go here.
B29: 2 | C29: 5 | D29: 70% | E29: =MROUND('Start Here'!$C$9*0.7,5) | F29: 7 | G29: 3-4 min
B30: 3 | C30: 5 | D30: 70% | E30: =MROUND('Start Here'!$C$9*0.7,5) | F30: 7 | G30: 3-4 min
A31: Paused Squat (2-ct) | B31: 1 | C31: 5 | D31: 62.5% | E31: =MROUND('Start Here'!$C$7*0.625,5) | F31: 7 | G31: 3-4 min | H31: 2-second dead-stop in the hole, stay braced and upright, no bounce. Builds bottom-position strength and quad size. Own the pause — don't rush it.
B32: 2 | C32: 5 | D32: 62.5% | E32: =MROUND('Start Here'!$C$7*0.625,5) | F32: 7 | G32: 3-4 min
B33: 3 | C33: 5 | D33: 62.5% | E33: =MROUND('Start Here'!$C$7*0.625,5) | F33: 7 | G33: 3-4 min
A34: Bulgarian Split Squat | B34: 3 | C34: 8-10 /leg | D34: — | E34: Your pick | F34: 8 | G34: 2 min | H34: Rear foot elevated, slight forward lean for glutes, upright for quads — pick your target. This is your athleticism builder: balance, single-leg strength, hip stability. Start with 40-50 lb DBs.
A35: Back Extension (glute bias) | B35: 3 | C35: 12-15 | D35: — | E35: Your pick | F35: 8-9 | G35: 90 sec | H35: Round upper back slightly, tuck chin, squeeze glutes to lift — don't hyperextend the spine. Hold a plate when 15 gets easy.
A36: Walking DB Lunge | B36: 2 | C36: 20 steps | D36: — | E36: Your pick | F36: 8 | G36: 2 min | H36: Long strides, soft knee touch, continuous walking. Brutal and athletic. Light DBs are plenty after everything else.
A37: Seated Calf Raise | B37: 4 | C37: 12-15 | D37: — | E37: Your pick | F37: 8-9 | G37: 60-90 sec | H37: Soleus focus. Slow 3-sec negative, deep stretch, pause at top.
A38: Hanging Leg Raise | B38: 3 | C38: 10-15 | D38: — | E38: Your pick | F38: 8 | G38: 90 sec | H38: Posterior pelvic tilt at the top — curl the pelvis up, don't just swing the legs. Bend knees if needed.
A40: SUNDAY — UPPER B: VOLUME BENCH + PUMP DAY (long session — chase the pump)
A41: Exercise | B41: Set | C41: Target Reps | D41: %1RM | E41: Target Weight | F41: Target RPE | G41: Rest | H41: Coaching Cues / Special Instructions | I41: Actual Weight | J41: Actual Reps | K41: Actual RPE | L41: Set Notes (how it felt, bar speed, pump, tweaks)
A42: Touch-and-Go Bench | B42: 1 | C42: 8 | D42: 65% | E42: =MROUND('Start Here'!$C$8*0.65,5) | F42: 7-8 | G42: 3-4 min | H42: Smooth touch, no bounce off the chest. Slight tuck, squeeze pecs hard at lockout each rep. This is a muscle set, not a strength test — chase the pec pump.
B43: 2 | C43: 8 | D43: 65% | E43: =MROUND('Start Here'!$C$8*0.65,5) | F43: 7-8 | G43: 3-4 min
...

Sheet Week 2
A1: FORGED 4-DAY POWERBUILDER — WEEK 2 | BLOCK 1: VOLUME & MOVEMENT QUALITY
A2: TUESDAY — LOWER A: SQUAT STRENGTH + POSTERIOR CHAIN (target: ≤85 min)
A3: Exercise | B3: Set | C3: Target Reps | D3: %1RM | E3: Target Weight | F3: Target RPE | G3: Rest | H3: Coaching Cues / Special Instructions | I3: Actual Weight | J3: Actual Reps | K3: Actual RPE | L3: Set Notes (how it felt, bar speed, pump, tweaks)
A4: Competition Squat | B4: 1 | C4: 6 | D4: 72.5% | E4: =MROUND('Start Here'!$C$7*0.725,5) | F4: 7.5 | G4: 3-4 min | H4: Full comp setup every set: same walkout, same bracing. Big 360° breath, spread the floor, drive up through mid-foot. Treat every rep like a platform rep.
B5: 2 | C5: 6 | D5: 72.5% | E5: =MROUND('Start Here'!$C$7*0.725,5) | F5: 7.5 | G5: 3-4 min
B6: 3 | C6: 6 | D6: 72.5% | E6: =MROUND('Start Here'!$C$7*0.725,5) | F6: 7.5 | G6: 3-4 min
B7: 4 | C7: 6 | D7: 72.5% | E7: =MROUND('Start Here'!$C$7*0.725,5) | F7: 7.5 | G7: 3-4 min
A8: Romanian Deadlift | B8: 3 | C8: 8-10 | D8: — | E8: Your pick | F8: 7-8 | G8: 2-3 min | H8: Soft knees, push hips back until hamstrings scream, bar drags the thighs. Start ~185-225 and add when all sets hit 10. Feel the stretch — that's the growth signal.
A9: Leg Press (feet low & narrow) | B9: 3 | C9: 10-12 | D9: — | E9: Your pick | F9: 8 | G9: 2 min | H9: Quad-bias stance. Full depth without butt tucking, 2-sec lowering. Drive knees over toes. Don't chase plates — chase the quad burn.
A10: Seated Leg Curl | B10: 3 | C10: 12-15 | D10: — | E10: Your pick | F10: 8-9 | G10: 90 sec | H10: Lean torso forward slightly for a longer hamstring stretch. Squeeze 1 sec at full flexion, 3-sec lowering.
A11: Standing Calf Raise | B11: 3 | C11: 10-12 | D11: — | E11: Your pick | F11: 8-9 | G11: 90 sec | H11: Full stretch at the bottom for a 2-count, drive through the big toe, pause at the top. No bouncing.
A12: Cable Crunch | B12: 3 | C12: 12-15 | D12: — | E12: Your pick | F12: 8 | G12: 60-90 sec | H12: Flex the spine — ribs to hips, don't just bow at the waist. Strong abs = strong squat brace.
A14: THURSDAY — UPPER A: BENCH STRENGTH + BACK (target: ≤85 min)
A15: Exercise | B15: Set | C15: Target Reps | D15: %1RM | E15: Target Weight | F15: Target RPE | G15: Rest | H15: Coaching Cues / Special Instructions | I15: Actual Weight | J15: Actual Reps | K15: Actual RPE | L15: Set Notes (how it felt, bar speed, pump, tweaks)
A16: Competition Bench | B16: 1 | C16: 6 | D16: 72.5% | E16: =MROUND('Start Here'!$C$8*0.725,5) | F16: 7.5 | G16: 3-4 min | H16: Comp pause on every rep this day. Set your arch, pull the bar apart, tuck elbows ~45°, press back over your face. Leg drive on.
B17: 2 | C17: 6 | D17: 72.5% | E17: =MROUND('Start Here'!$C$8*0.725,5) | F17: 7.5 | G17: 3-4 min
B18: 3 | C18: 6 | D18: 72.5% | E18: =MROUND('Start Here'!$C$8*0.725,5) | F18: 7.5 | G18: 3-4 min
B19: 4 | C19: 6 | D19: 72.5% | E19: =MROUND('Start Here'!$C$8*0.725,5) | F19: 7.5 | G19: 3-4 min
A20: Weighted Pull-Up | B20: 4 | C20: 6-8 | D20: — | E20: Your pick | F20: 8 | G20: 2-3 min | H20: Add weight when you own 4x8 at bodyweight+. Dead hang start, drive elbows to hips, chest to bar. Lats build your bench arch and your V-taper.
A21: Seated DB Shoulder Press | B21: 3 | C21: 8-10 | D21: — | E21: Your pick | F21: 8 | G21: 2 min | H21: Slight back support, press up-and-in, stop just short of lockout to keep tension on delts. Start ~55-65s.
A22: Chest-Supported Row | B22: 3 | C22: 10-12 | D22: — | E22: Your pick | F22: 8 | G22: 90 sec | H22: Chest glued to pad — no cheating with body English. Pull to lower ribs, squeeze the shoulder blades for 1 sec.
A23: SUPERSET: EZ-Bar Curl + Overhead Cable Extension | B23: 3 | C23: 10-12 each | D23: — | E23: Your pick | F23: 8 | G23: 90 sec after pair | H23: Curls: elbows pinned, no swing. Overhead extensions: full stretch behind head — long-head triceps grow from the stretch. Alternate exercises, rest after both.
A24: Face Pull | B24: 3 | C24: 15-20 | D24: — | E24: Your pick | F24: 8 | G24: 60 sec | H24: Rope to forehead, thumbs back, external rotate at the end. Shoulder insurance — never skip these.
A26: SATURDAY — LOWER B: DEADLIFT + ATHLETIC LOWER (long session — take your time)
A27: Exercise | B27: Set | C27: Target Reps | D27: %1RM | E27: Target Weight | F27: Target RPE | G27: Rest | H27: Coaching Cues / Special Instructions | I27: Actual Weight | J27: Actual Reps | K27: Actual RPE | L27: Set Notes (how it felt, bar speed, pump, tweaks)
A28: Deadlift | B28: 1 | C28: 5 | D28: 72.5% | E28: =MROUND('Start Here'!$C$9*0.725,5) | F28: 7.5 | G28: 3-4 min | H28: Wedge hard, pull the slack out until the bar clicks, push the floor away. Hips and shoulders rise together. Reset every rep — no touch-and-go here.
B29: 2 | C29: 5 | D29: 72.5% | E29: =MROUND('Start Here'!$C$9*0.725,5) | F29: 7.5 | G29: 3-4 min
B30: 3 | C30: 5 | D30: 72.5% | E30: =MROUND('Start Here'!$C$9*0.725,5) | F30: 7.5 | G30: 3-4 min
A31: Paused Squat (2-ct) | B31: 1 | C31: 5 | D31: 65% | E31: =MROUND('Start Here'!$C$7*0.65,5) | F31: 7.5 | G31: 3-4 min | H31: 2-second dead-stop in the hole, stay braced and upright, no bounce. Builds bottom-position strength and quad size. Own the pause — don't rush it.
B32: 2 | C32: 5 | D32: 65% | E32: =MROUND('Start Here'!$C$7*0.65,5) | F32: 7.5 | G32: 3-4 min
B33: 3 | C33: 5 | D33: 65% | E33: =MROUND('Start Here'!$C$7*0.65,5) | F33: 7.5 | G33: 3-4 min
A34: Bulgarian Split Squat | B34: 3 | C34: 8-10 /leg | D34: — | E34: Your pick | F34: 8 | G34: 2 min | H34: Rear foot elevated, slight forward lean for glutes, upright for quads — pick your target. This is your athleticism builder: balance, single-leg strength, hip stability. Start with 40-50 lb DBs.
A35: Back Extension (glute bias) | B35: 3 | C35: 12-15 | D35: — | E35: Your pick | F35: 8-9 | G35: 90 sec | H35: Round upper back slightly, tuck chin, squeeze glutes to lift — don't hyperextend the spine. Hold a plate when 15 gets easy.
A36: Walking DB Lunge | B36: 2 | C36: 20 steps | D36: — | E36: Your pick | F36: 8 | G36: 2 min | H36: Long strides, soft knee touch, continuous walking. Brutal and athletic. Light DBs are plenty after everything else.
A37: Seated Calf Raise | B37: 4 | C37: 12-15 | D37: — | E37: Your pick | F37: 8-9 | G37: 60-90 sec | H37: Soleus focus. Slow 3-sec negative, deep stretch, pause at top.
A38: Hanging Leg Raise | B38: 3 | C38: 10-15 | D38: — | E38: Your pick | F38: 8 | G38: 90 sec | H38: Posterior pelvic tilt at the top — curl the pelvis up, don't just swing the legs. Bend knees if needed.
A40: SUNDAY — UPPER B: VOLUME BENCH + PUMP DAY (long session — chase the pump)
A41: Exercise | B41: Set | C41: Target Reps | D41: %1RM | E41: Target Weight | F41: Target RPE | G41: Rest | H41: Coaching Cues / Special Instructions | I41: Actual Weight | J41: Actual Reps | K41: Actual RPE | L41: Set Notes (how it felt, bar speed, pump, tweaks)
A42: Touch-and-Go Bench | B42: 1 | C42: 8 | D42: 67.5% | E42: =MROUND('Start Here'!$C$8*0.675,5) | F42: 7-8 | G42: 3-4 min | H42: Smooth touch, no bounce off the chest. Slight tuck, squeeze pecs hard at lockout each rep. This is a muscle set, not a strength test — chase the pec pump.
B43: 2 | C43: 8 | D43: 67.5% | E43: =MROUND('Start Here'!$C$8*0.675,5) | F43: 7-8 | G43: 3-4 min
...

Sheet Week 3
A1: FORGED 4-DAY POWERBUILDER — WEEK 3 | BLOCK 1: VOLUME & MOVEMENT QUALITY
A2: TUESDAY — LOWER A: SQUAT STRENGTH + POSTERIOR CHAIN (target: ≤85 min)
A3: Exercise | B3: Set | C3: Target Reps | D3: %1RM | E3: Target Weight | F3: Target RPE | G3: Rest | H3: Coaching Cues / Special Instructions | I3: Actual Weight | J3: Actual Reps | K3: Actual RPE | L3: Set Notes (how it felt, bar speed, pump, tweaks)
A4: Competition Squat | B4: 1 | C4: 5 | D4: 75% | E4: =MROUND('Start Here'!$C$7*0.75,5) | F4: 8 | G4: 3-4 min | H4: Full comp setup every set: same walkout, same bracing. Big 360° breath, spread the floor, drive up through mid-foot. Treat every rep like a platform rep.
B5: 2 | C5: 5 | D5: 75% | E5: =MROUND('Start Here'!$C$7*0.75,5) | F5: 8 | G5: 3-4 min
B6: 3 | C6: 5 | D6: 75% | E6: =MROUND('Start Here'!$C$7*0.75,5) | F6: 8 | G6: 3-4 min
B7: 4 | C7: 5 | D7: 75% | E7: =MROUND('Start Here'!$C$7*0.75,5) | F7: 8 | G7: 3-4 min
A8: Romanian Deadlift | B8: 3 | C8: 8-10 | D8: — | E8: Your pick | F8: 7-8 | G8: 2-3 min | H8: Soft knees, push hips back until hamstrings scream, bar drags the thighs. Start ~185-225 and add when all sets hit 10. Feel the stretch — that's the growth signal.
A9: Leg Press (feet low & narrow) | B9: 3 | C9: 10-12 | D9: — | E9: Your pick | F9: 8 | G9: 2 min | H9: Quad-bias stance. Full depth without butt tucking, 2-sec lowering. Drive knees over toes. Don't chase plates — chase the quad burn.
A10: Seated Leg Curl | B10: 3 | C10: 12-15 | D10: — | E10: Your pick | F10: 8-9 | G10: 90 sec | H10: Lean torso forward slightly for a longer hamstring stretch. Squeeze 1 sec at full flexion, 3-sec lowering.
A11: Standing Calf Raise | B11: 3 | C11: 10-12 | D11: — | E11: Your pick | F11: 8-9 | G11: 90 sec | H11: Full stretch at the bottom for a 2-count, drive through the big toe, pause at the top. No bouncing.
A12: Cable Crunch | B12: 3 | C12: 12-15 | D12: — | E12: Your pick | F12: 8 | G12: 60-90 sec | H12: Flex the spine — ribs to hips, don't just bow at the waist. Strong abs = strong squat brace.
A14: THURSDAY — UPPER A: BENCH STRENGTH + BACK (target: ≤85 min)
A15: Exercise | B15: Set | C15: Target Reps | D15: %1RM | E15: Target Weight | F15: Target RPE | G15: Rest | H15: Coaching Cues / Special Instructions | I15: Actual Weight | J15: Actual Reps | K15: Actual RPE | L15: Set Notes (how it felt, bar speed, pump, tweaks)
A16: Competition Bench | B16: 1 | C16: 5 | D16: 75% | E16: =MROUND('Start Here'!$C$8*0.75,5) | F16: 8 | G16: 3-4 min | H16: Comp pause on every rep this day. Set your arch, pull the bar apart, tuck elbows ~45°, press back over your face. Leg drive on.
B17: 2 | C17: 5 | D17: 75% | E17: =MROUND('Start Here'!$C$8*0.75,5) | F17: 8 | G17: 3-4 min
B18: 3 | C18: 5 | D18: 75% | E18: =MROUND('Start Here'!$C$8*0.75,5) | F18: 8 | G18: 3-4 min
B19: 4 | C19: 5 | D19: 75% | E19: =MROUND('Start Here'!$C$8*0.75,5) | F19: 8 | G19: 3-4 min
A20: Weighted Pull-Up | B20: 4 | C20: 6-8 | D20: — | E20: Your pick | F20: 8 | G20: 2-3 min | H20: Add weight when you own 4x8 at bodyweight+. Dead hang start, drive elbows to hips, chest to bar. Lats build your bench arch and your V-taper.
A21: Seated DB Shoulder Press | B21: 3 | C21: 8-10 | D21: — | E21: Your pick | F21: 8 | G21: 2 min | H21: Slight back support, press up-and-in, stop just short of lockout to keep tension on delts. Start ~55-65s.
A22: Chest-Supported Row | B22: 3 | C22: 10-12 | D22: — | E22: Your pick | F22: 8 | G22: 90 sec | H22: Chest glued to pad — no cheating with body English. Pull to lower ribs, squeeze the shoulder blades for 1 sec.
A23: SUPERSET: EZ-Bar Curl + Overhead Cable Extension | B23: 3 | C23: 10-12 each | D23: — | E23: Your pick | F23: 8 | G23: 90 sec after pair | H23: Curls: elbows pinned, no swing. Overhead extensions: full stretch behind head — long-head triceps grow from the stretch. Alternate exercises, rest after both.
A24: Face Pull | B24: 3 | C24: 15-20 | D24: — | E24: Your pick | F24: 8 | G24: 60 sec | H24: Rope to forehead, thumbs back, external rotate at the end. Shoulder insurance — never skip these.
A26: SATURDAY — LOWER B: DEADLIFT + ATHLETIC LOWER (long session — take your time)
A27: Exercise | B27: Set | C27: Target Reps | D27: %1RM | E27: Target Weight | F27: Target RPE | G27: Rest | H27: Coaching Cues / Special Instructions | I27: Actual Weight | J27: Actual Reps | K27: Actual RPE | L27: Set Notes (how it felt, bar speed, pump, tweaks)
A28: Deadlift | B28: 1 | C28: 4 | D28: 75% | E28: =MROUND('Start Here'!$C$9*0.75,5) | F28: 8 | G28: 3-4 min | H28: Wedge hard, pull the slack out until the bar clicks, push the floor away. Hips and shoulders rise together. Reset every rep — no touch-and-go here.
B29: 2 | C29: 4 | D29: 75% | E29: =MROUND('Start Here'!$C$9*0.75,5) | F29: 8 | G29: 3-4 min
B30: 3 | C30: 4 | D30: 75% | E30: =MROUND('Start Here'!$C$9*0.75,5) | F30: 8 | G30: 3-4 min
A31: Paused Squat (2-ct) | B31: 1 | C31: 4 | D31: 67.5% | E31: =MROUND('Start Here'!$C$7*0.675,5) | F31: 8 | G31: 3-4 min | H31: 2-second dead-stop in the hole, stay braced and upright, no bounce. Builds bottom-position strength and quad size. Own the pause — don't rush it.
B32: 2 | C32: 4 | D32: 67.5% | E32: =MROUND('Start Here'!$C$7*0.675,5) | F32: 8 | G32: 3-4 min
B33: 3 | C33: 4 | D33: 67.5% | E33: =MROUND('Start Here'!$C$7*0.675,5) | F33: 8 | G33: 3-4 min
A34: Bulgarian Split Squat | B34: 3 | C34: 8-10 /leg | D34: — | E34: Your pick | F34: 8 | G34: 2 min | H34: Rear foot elevated, slight forward lean for glutes, upright for quads — pick your target. This is your athleticism builder: balance, single-leg strength, hip stability. Start with 40-50 lb DBs.
A35: Back Extension (glute bias) | B35: 3 | C35: 12-15 | D35: — | E35: Your pick | F35: 8-9 | G35: 90 sec | H35: Round upper back slightly, tuck chin, squeeze glutes to lift — don't hyperextend the spine. Hold a plate when 15 gets easy.
A36: Walking DB Lunge | B36: 2 | C36: 20 steps | D36: — | E36: Your pick | F36: 8 | G36: 2 min | H36: Long strides, soft knee touch, continuous walking. Brutal and athletic. Light DBs are plenty after everything else.
A37: Seated Calf Raise | B37: 4 | C37: 12-15 | D37: — | E37: Your pick | F37: 8-9 | G37: 60-90 sec | H37: Soleus focus. Slow 3-sec negative, deep stretch, pause at top.
A38: Hanging Leg Raise | B38: 3 | C38: 10-15 | D38: — | E38: Your pick | F38: 8 | G38: 90 sec | H38: Posterior pelvic tilt at the top — curl the pelvis up, don't just swing the legs. Bend knees if needed.
A40: SUNDAY — UPPER B: VOLUME BENCH + PUMP DAY (long session — chase the pump)
A41: Exercise | B41: Set | C41: Target Reps | D41: %1RM | E41: Target Weight | F41: Target RPE | G41: Rest | H41: Coaching Cues / Special Instructions | I41: Actual Weight | J41: Actual Reps | K41: Actual RPE | L41: Set Notes (how it felt, bar speed, pump, tweaks)
A42: Touch-and-Go Bench | B42: 1 | C42: 8 | D42: 70% | E42: =MROUND('Start Here'!$C$8*0.7,5) | F42: 8 | G42: 3-4 min | H42: Smooth touch, no bounce off the chest. Slight tuck, squeeze pecs hard at lockout each rep. This is a muscle set, not a strength test — chase the pec pump.
B43: 2 | C43: 8 | D43: 70% | E43: =MROUND('Start Here'!$C$8*0.7,5) | F43: 8 | G43: 3-4 min
...

Sheet Week 4
A1: FORGED 4-DAY POWERBUILDER — WEEK 4 | BLOCK 1: VOLUME & MOVEMENT QUALITY • DELOAD WEEK — recover, move fast, leave feeling fresh
A2: TUESDAY — LOWER A: SQUAT STRENGTH + POSTERIOR CHAIN (target: ≤85 min)
A3: Exercise | B3: Set | C3: Target Reps | D3: %1RM | E3: Target Weight | F3: Target RPE | G3: Rest | H3: Coaching Cues / Special Instructions | I3: Actual Weight | J3: Actual Reps | K3: Actual RPE | L3: Set Notes (how it felt, bar speed, pump, tweaks)
A4: Competition Squat | B4: 1 | C4: 5 | D4: 60% | E4: =MROUND('Start Here'!$C$7*0.6,5) | F4: ≤6 | G4: 3-4 min | H4: Full comp setup every set: same walkout, same bracing. Big 360° breath, spread the floor, drive up through mid-foot. Treat every rep like a platform rep. DELOAD — crisp bar speed, nothing grindy.
B5: 2 | C5: 5 | D5: 60% | E5: =MROUND('Start Here'!$C$7*0.6,5) | F5: ≤6 | G5: 3-4 min
B6: 3 | C6: 5 | D6: 60% | E6: =MROUND('Start Here'!$C$7*0.6,5) | F6: ≤6 | G6: 3-4 min
A7: Romanian Deadlift | B7: 2 | C7: 8-10 | D7: — | E7: Your pick | F7: 6-7 | G7: 2-3 min | H7: DELOAD: 2 easy sets, stay 3-4 reps from failure. Soft knees, push hips back until hamstrings scream, bar drags the thighs. Start ~185-225 and add when all sets hit 10. Feel the stretch — that's the growth signal.
A8: Leg Press (feet low & narrow) | B8: 2 | C8: 10-12 | D8: — | E8: Your pick | F8: 6-7 | G8: 2 min | H8: DELOAD: 2 easy sets, stay 3-4 reps from failure. Quad-bias stance. Full depth without butt tucking, 2-sec lowering. Drive knees over toes. Don't chase plates — chase the quad burn.
A9: Seated Leg Curl | B9: 2 | C9: 12-15 | D9: — | E9: Your pick | F9: 6-7 | G9: 90 sec | H9: DELOAD: 2 easy sets, stay 3-4 reps from failure. Lean torso forward slightly for a longer hamstring stretch. Squeeze 1 sec at full flexion, 3-sec lowering.
A10: Standing Calf Raise | B10: 2 | C10: 10-12 | D10: — | E10: Your pick | F10: 6-7 | G10: 90 sec | H10: DELOAD: 2 easy sets, stay 3-4 reps from failure. Full stretch at the bottom for a 2-count, drive through the big toe, pause at the top. No bouncing.
A11: Cable Crunch | B11: 2 | C11: 12-15 | D11: — | E11: Your pick | F11: 6-7 | G11: 60-90 sec | H11: DELOAD: 2 easy sets, stay 3-4 reps from failure. Flex the spine — ribs to hips, don't just bow at the waist. Strong abs = strong squat brace.
A13: THURSDAY — UPPER A: BENCH STRENGTH + BACK (target: ≤85 min)
A14: Exercise | B14: Set | C14: Target Reps | D14: %1RM | E14: Target Weight | F14: Target RPE | G14: Rest | H14: Coaching Cues / Special Instructions | I14: Actual Weight | J14: Actual Reps | K14: Actual RPE | L14: Set Notes (how it felt, bar speed, pump, tweaks)
A15: Competition Bench | B15: 1 | C15: 5 | D15: 60% | E15: =MROUND('Start Here'!$C$8*0.6,5) | F15: ≤6 | G15: 3-4 min | H15: Comp pause on every rep this day. Set your arch, pull the bar apart, tuck elbows ~45°, press back over your face. Leg drive on. DELOAD — perfect technique reps only.
B16: 2 | C16: 5 | D16: 60% | E16: =MROUND('Start Here'!$C$8*0.6,5) | F16: ≤6 | G16: 3-4 min
B17: 3 | C17: 5 | D17: 60% | E17: =MROUND('Start Here'!$C$8*0.6,5) | F17: ≤6 | G17: 3-4 min
A18: Weighted Pull-Up | B18: 3 | C18: 6-8 | D18: — | E18: Your pick | F18: 6-7 | G18: 2-3 min | H18: DELOAD: 3 easy sets, stay 3-4 reps from failure. Add weight when you own 4x8 at bodyweight+. Dead hang start, drive elbows to hips, chest to bar. Lats build your bench arch and your V-taper.
A19: Seated DB Shoulder Press | B19: 2 | C19: 8-10 | D19: — | E19: Your pick | F19: 6-7 | G19: 2 min | H19: DELOAD: 2 easy sets, stay 3-4 reps from failure. Slight back support, press up-and-in, stop just short of lockout to keep tension on delts. Start ~55-65s.
A20: Chest-Supported Row | B20: 2 | C20: 10-12 | D20: — | E20: Your pick | F20: 6-7 | G20: 90 sec | H20: DELOAD: 2 easy sets, stay 3-4 reps from failure. Chest glued to pad — no cheating with body English. Pull to lower ribs, squeeze the shoulder blades for 1 sec.
A21: SUPERSET: EZ-Bar Curl + Overhead Cable Extension | B21: 2 | C21: 10-12 each | D21: — | E21: Your pick | F21: 6-7 | G21: 90 sec after pair | H21: DELOAD: 2 easy sets, stay 3-4 reps from failure. Curls: elbows pinned, no swing. Overhead extensions: full stretch behind head — long-head triceps grow from the stretch. Alternate exercises, rest after both.
A22: Face Pull | B22: 2 | C22: 15-20 | D22: — | E22: Your pick | F22: 6-7 | G22: 60 sec | H22: DELOAD: 2 easy sets, stay 3-4 reps from failure. Rope to forehead, thumbs back, external rotate at the end. Shoulder insurance — never skip these.
A24: SATURDAY — LOWER B: DEADLIFT + ATHLETIC LOWER (long session — take your time)
A25: Exercise | B25: Set | C25: Target Reps | D25: %1RM | E25: Target Weight | F25: Target RPE | G25: Rest | H25: Coaching Cues / Special Instructions | I25: Actual Weight | J25: Actual Reps | K25: Actual RPE | L25: Set Notes (how it felt, bar speed, pump, tweaks)
A26: Deadlift | B26: 1 | C26: 4 | D26: 60% | E26: =MROUND('Start Here'!$C$9*0.6,5) | F26: ≤6 | G26: 3-4 min | H26: Wedge hard, pull the slack out until the bar clicks, push the floor away. Hips and shoulders rise together. Reset every rep — no touch-and-go here. DELOAD — speed pulls, perfect positions.
B27: 2 | C27: 4 | D27: 60% | E27: =MROUND('Start Here'!$C$9*0.6,5) | F27: ≤6 | G27: 3-4 min
A28: Paused Squat (2-ct) | B28: 1 | C28: 5 | D28: 55% | E28: =MROUND('Start Here'!$C$7*0.55,5) | F28: ≤6 | G28: 3-4 min | H28: 2-second dead-stop in the hole, stay braced and upright, no bounce. Builds bottom-position strength and quad size. Own the pause — don't rush it.
B29: 2 | C29: 5 | D29: 55% | E29: =MROUND('Start Here'!$C$7*0.55,5) | F29: ≤6 | G29: 3-4 min
A30: Bulgarian Split Squat | B30: 2 | C30: 8-10 /leg | D30: — | E30: Your pick | F30: 6-7 | G30: 2 min | H30: DELOAD: 2 easy sets, stay 3-4 reps from failure. Rear foot elevated, slight forward lean for glutes, upright for quads — pick your target. This is your athleticism builder: balance, single-leg strength, hip stability. Start with 40-50 lb DBs.
A31: Back Extension (glute bias) | B31: 2 | C31: 12-15 | D31: — | E31: Your pick | F31: 6-7 | G31: 90 sec | H31: DELOAD: 2 easy sets, stay 3-4 reps from failure. Round upper back slightly, tuck chin, squeeze glutes to lift — don't hyperextend the spine. Hold a plate when 15 gets easy.
A32: Walking DB Lunge | B32: 2 | C32: 20 steps | D32: — | E32: Your pick | F32: 6-7 | G32: 2 min | H32: DELOAD: 2 easy sets, stay 3-4 reps from failure. Long strides, soft knee touch, continuous walking. Brutal and athletic. Light DBs are plenty after everything else.
A33: Seated Calf Raise | B33: 3 | C33: 12-15 | D33: — | E33: Your pick | F33: 6-7 | G33: 60-90 sec | H33: DELOAD: 3 easy sets, stay 3-4 reps from failure. Soleus focus. Slow 3-sec negative, deep stretch, pause at top.
A34: Hanging Leg Raise | B34: 2 | C34: 10-15 | D34: — | E34: Your pick | F34: 6-7 | G34: 90 sec | H34: DELOAD: 2 easy sets, stay 3-4 reps from failure. Posterior pelvic tilt at the top — curl the pelvis up, don't just swing the legs. Bend knees if needed.
A36: SUNDAY — UPPER B: VOLUME BENCH + PUMP DAY (long session — chase the pump)
A37: Exercise | B37: Set | C37: Target Reps | D37: %1RM | E37: Target Weight | F37: Target RPE | G37: Rest | H37: Coaching Cues / Special Instructions | I37: Actual Weight | J37: Actual Reps | K37: Actual RPE | L37: Set Notes (how it felt, bar speed, pump, tweaks)
A38: Touch-and-Go Bench | B38: 1 | C38: 8 | D38: 55% | E38: =MROUND('Start Here'!$C$8*0.55,5) | F38: ≤6 | G38: 3-4 min | H38: Smooth touch, no bounce off the chest. Slight tuck, squeeze pecs hard at lockout each rep. This is a muscle set, not a strength test — chase the pec pump.
B39: 2 | C39: 8 | D39: 55% | E39: =MROUND('Start Here'!$C$8*0.55,5) | F39: ≤6 | G39: 3-4 min
B40: 3 | C40: 8 | D40: 55% | E40: =MROUND('Start Here'!$C$8*0.55,5) | F40: ≤6 | G40: 3-4 min
A41: Incline DB Press (30°) | B41: 2 | C41: 10-12 | D41: — | E41: Your pick | F41: 6-7 | G41: 2 min | H41: DELOAD: 2 easy sets, stay 3-4 reps from failure. Deep stretch at the bottom, press up-and-in, squeeze upper pecs at top. Don't touch the DBs together hard — keep tension. Start ~75-85s.
A42: Lat Pulldown (neutral wide) | B42: 3 | C42: 10-12 | D42: — | E42: Your pick | F42: 6-7 | G42: 90 sec | H42: DELOAD: 3 easy sets, stay 3-4 reps from failure. Drive elbows down and back, pause 1 sec at the chest, 3-sec controlled return. Think 'elbows in back pockets' — feel the lats, not the arms.
A43: Single-Arm Cable Row | B43: 2 | C43: 10-12 /arm | D43: — | E43: Your pick | F43: 6-7 | G43: 90 sec | H43: DELOAD: 2 easy sets, stay 3-4 reps from failure. Allow a full stretch and slight rotation forward, then row and squeeze. One side at a time = maximum mind-muscle connection.
...

Sheet Week 5
A1: FORGED 4-DAY POWERBUILDER — WEEK 5 | BLOCK 2: STRENGTH EXPRESSION
A2: TUESDAY — LOWER A: SQUAT STRENGTH + POSTERIOR CHAIN (target: ≤85 min)
A3: Exercise | B3: Set | C3: Target Reps | D3: %1RM | E3: Target Weight | F3: Target RPE | G3: Rest | H3: Coaching Cues / Special Instructions | I3: Actual Weight | J3: Actual Reps | K3: Actual RPE | L3: Set Notes (how it felt, bar speed, pump, tweaks)
A4: Competition Squat | B4: 1 | C4: 4 | D4: 77.5% | E4: =MROUND('Start Here'!$C$7*0.775,5) | F4: 7.5 | G4: 3-4 min | H4: Full comp setup every set: same walkout, same bracing. Big 360° breath, spread the floor, drive up through mid-foot. Treat every rep like a platform rep.
B5: 2 | C5: 4 | D5: 77.5% | E5: =MROUND('Start Here'!$C$7*0.775,5) | F5: 7.5 | G5: 3-4 min
B6: 3 | C6: 4 | D6: 77.5% | E6: =MROUND('Start Here'!$C$7*0.775,5) | F6: 7.5 | G6: 3-4 min
B7: 4 | C7: 4 | D7: 77.5% | E7: =MROUND('Start Here'!$C$7*0.775,5) | F7: 7.5 | G7: 3-4 min
A8: Romanian Deadlift | B8: 3 | C8: 8-10 | D8: — | E8: Your pick | F8: 7-8 | G8: 2-3 min | H8: Soft knees, push hips back until hamstrings scream, bar drags the thighs. Start ~185-225 and add when all sets hit 10. Feel the stretch — that's the growth signal.
A9: Leg Press (feet low & narrow) | B9: 3 | C9: 10-12 | D9: — | E9: Your pick | F9: 8 | G9: 2 min | H9: Quad-bias stance. Full depth without butt tucking, 2-sec lowering. Drive knees over toes. Don't chase plates — chase the quad burn.
A10: Seated Leg Curl | B10: 3 | C10: 12-15 | D10: — | E10: Your pick | F10: 8-9 | G10: 90 sec | H10: Lean torso forward slightly for a longer hamstring stretch. Squeeze 1 sec at full flexion, 3-sec lowering.
A11: Standing Calf Raise | B11: 3 | C11: 10-12 | D11: — | E11: Your pick | F11: 8-9 | G11: 90 sec | H11: Full stretch at the bottom for a 2-count, drive through the big toe, pause at the top. No bouncing.
A12: Cable Crunch | B12: 3 | C12: 12-15 | D12: — | E12: Your pick | F12: 8 | G12: 60-90 sec | H12: Flex the spine — ribs to hips, don't just bow at the waist. Strong abs = strong squat brace.
A14: THURSDAY — UPPER A: BENCH STRENGTH + BACK (target: ≤85 min)
A15: Exercise | B15: Set | C15: Target Reps | D15: %1RM | E15: Target Weight | F15: Target RPE | G15: Rest | H15: Coaching Cues / Special Instructions | I15: Actual Weight | J15: Actual Reps | K15: Actual RPE | L15: Set Notes (how it felt, bar speed, pump, tweaks)
A16: Competition Bench | B16: 1 | C16: 4 | D16: 77.5% | E16: =MROUND('Start Here'!$C$8*0.775,5) | F16: 7.5 | G16: 3-4 min | H16: Comp pause on every rep this day. Set your arch, pull the bar apart, tuck elbows ~45°, press back over your face. Leg drive on.
B17: 2 | C17: 4 | D17: 77.5% | E17: =MROUND('Start Here'!$C$8*0.775,5) | F17: 7.5 | G17: 3-4 min
B18: 3 | C18: 4 | D18: 77.5% | E18: =MROUND('Start Here'!$C$8*0.775,5) | F18: 7.5 | G18: 3-4 min
B19: 4 | C19: 4 | D19: 77.5% | E19: =MROUND('Start Here'!$C$8*0.775,5) | F19: 7.5 | G19: 3-4 min
A20: Weighted Pull-Up | B20: 4 | C20: 6-8 | D20: — | E20: Your pick | F20: 8 | G20: 2-3 min | H20: Add weight when you own 4x8 at bodyweight+. Dead hang start, drive elbows to hips, chest to bar. Lats build your bench arch and your V-taper.
A21: Seated DB Shoulder Press | B21: 3 | C21: 8-10 | D21: — | E21: Your pick | F21: 8 | G21: 2 min | H21: Slight back support, press up-and-in, stop just short of lockout to keep tension on delts. Start ~55-65s.
A22: Chest-Supported Row | B22: 3 | C22: 10-12 | D22: — | E22: Your pick | F22: 8 | G22: 90 sec | H22: Chest glued to pad — no cheating with body English. Pull to lower ribs, squeeze the shoulder blades for 1 sec.
A23: SUPERSET: EZ-Bar Curl + Overhead Cable Extension | B23: 3 | C23: 10-12 each | D23: — | E23: Your pick | F23: 8 | G23: 90 sec after pair | H23: Curls: elbows pinned, no swing. Overhead extensions: full stretch behind head — long-head triceps grow from the stretch. Alternate exercises, rest after both.
A24: Face Pull | B24: 3 | C24: 15-20 | D24: — | E24: Your pick | F24: 8 | G24: 60 sec | H24: Rope to forehead, thumbs back, external rotate at the end. Shoulder insurance — never skip these.
A26: SATURDAY — LOWER B: DEADLIFT + ATHLETIC LOWER (long session — take your time)
A27: Exercise | B27: Set | C27: Target Reps | D27: %1RM | E27: Target Weight | F27: Target RPE | G27: Rest | H27: Coaching Cues / Special Instructions | I27: Actual Weight | J27: Actual Reps | K27: Actual RPE | L27: Set Notes (how it felt, bar speed, pump, tweaks)
A28: Deadlift | B28: 1 | C28: 3 | D28: 77.5% | E28: =MROUND('Start Here'!$C$9*0.775,5) | F28: 7.5 | G28: 3-4 min | H28: Wedge hard, pull the slack out until the bar clicks, push the floor away. Hips and shoulders rise together. Reset every rep — no touch-and-go here.
B29: 2 | C29: 3 | D29: 77.5% | E29: =MROUND('Start Here'!$C$9*0.775,5) | F29: 7.5 | G29: 3-4 min
B30: 3 | C30: 3 | D30: 77.5% | E30: =MROUND('Start Here'!$C$9*0.775,5) | F30: 7.5 | G30: 3-4 min
A31: Paused Squat (2-ct) | B31: 1 | C31: 4 | D31: 67.5% | E31: =MROUND('Start Here'!$C$7*0.675,5) | F31: 7.5 | G31: 3-4 min | H31: 2-second dead-stop in the hole, stay braced and upright, no bounce. Builds bottom-position strength and quad size. Own the pause — don't rush it.
B32: 2 | C32: 4 | D32: 67.5% | E32: =MROUND('Start Here'!$C$7*0.675,5) | F32: 7.5 | G32: 3-4 min
B33: 3 | C33: 4 | D33: 67.5% | E33: =MROUND('Start Here'!$C$7*0.675,5) | F33: 7.5 | G33: 3-4 min
A34: Bulgarian Split Squat | B34: 3 | C34: 8-10 /leg | D34: — | E34: Your pick | F34: 8 | G34: 2 min | H34: Rear foot elevated, slight forward lean for glutes, upright for quads — pick your target. This is your athleticism builder: balance, single-leg strength, hip stability. Start with 40-50 lb DBs.
A35: Back Extension (glute bias) | B35: 3 | C35: 12-15 | D35: — | E35: Your pick | F35: 8-9 | G35: 90 sec | H35: Round upper back slightly, tuck chin, squeeze glutes to lift — don't hyperextend the spine. Hold a plate when 15 gets easy.
A36: Walking DB Lunge | B36: 2 | C36: 20 steps | D36: — | E36: Your pick | F36: 8 | G36: 2 min | H36: Long strides, soft knee touch, continuous walking. Brutal and athletic. Light DBs are plenty after everything else.
A37: Seated Calf Raise | B37: 4 | C37: 12-15 | D37: — | E37: Your pick | F37: 8-9 | G37: 60-90 sec | H37: Soleus focus. Slow 3-sec negative, deep stretch, pause at top.
A38: Hanging Leg Raise | B38: 3 | C38: 10-15 | D38: — | E38: Your pick | F38: 8 | G38: 90 sec | H38: Posterior pelvic tilt at the top — curl the pelvis up, don't just swing the legs. Bend knees if needed.
A40: SUNDAY — UPPER B: VOLUME BENCH + PUMP DAY (long session — chase the pump)
A41: Exercise | B41: Set | C41: Target Reps | D41: %1RM | E41: Target Weight | F41: Target RPE | G41: Rest | H41: Coaching Cues / Special Instructions | I41: Actual Weight | J41: Actual Reps | K41: Actual RPE | L41: Set Notes (how it felt, bar speed, pump, tweaks)
A42: Touch-and-Go Bench | B42: 1 | C42: 8 | D42: 67.5% | E42: =MROUND('Start Here'!$C$8*0.675,5) | F42: 7-8 | G42: 3-4 min | H42: Smooth touch, no bounce off the chest. Slight tuck, squeeze pecs hard at lockout each rep. This is a muscle set, not a strength test — chase the pec pump.
B43: 2 | C43: 8 | D43: 67.5% | E43: =MROUND('Start Here'!$C$8*0.675,5) | F43: 7-8 | G43: 3-4 min
...

Sheet Week 6
A1: FORGED 4-DAY POWERBUILDER — WEEK 6 | BLOCK 2: STRENGTH EXPRESSION
A2: TUESDAY — LOWER A: SQUAT STRENGTH + POSTERIOR CHAIN (target: ≤85 min)
A3: Exercise | B3: Set | C3: Target Reps | D3: %1RM | E3: Target Weight | F3: Target RPE | G3: Rest | H3: Coaching Cues / Special Instructions | I3: Actual Weight | J3: Actual Reps | K3: Actual RPE | L3: Set Notes (how it felt, bar speed, pump, tweaks)
A4: Competition Squat | B4: 1 | C4: 3 | D4: 80% | E4: =MROUND('Start Here'!$C$7*0.8,5) | F4: 8 | G4: 3-4 min | H4: Full comp setup every set: same walkout, same bracing. Big 360° breath, spread the floor, drive up through mid-foot. Treat every rep like a platform rep.
B5: 2 | C5: 3 | D5: 80% | E5: =MROUND('Start Here'!$C$7*0.8,5) | F5: 8 | G5: 3-4 min
B6: 3 | C6: 3 | D6: 80% | E6: =MROUND('Start Here'!$C$7*0.8,5) | F6: 8 | G6: 3-4 min
B7: 4 | C7: 3 | D7: 80% | E7: =MROUND('Start Here'!$C$7*0.8,5) | F7: 8 | G7: 3-4 min
A8: Romanian Deadlift | B8: 3 | C8: 8-10 | D8: — | E8: Your pick | F8: 7-8 | G8: 2-3 min | H8: Soft knees, push hips back until hamstrings scream, bar drags the thighs. Start ~185-225 and add when all sets hit 10. Feel the stretch — that's the growth signal.
A9: Leg Press (feet low & narrow) | B9: 3 | C9: 10-12 | D9: — | E9: Your pick | F9: 8 | G9: 2 min | H9: Quad-bias stance. Full depth without butt tucking, 2-sec lowering. Drive knees over toes. Don't chase plates — chase the quad burn.
A10: Seated Leg Curl | B10: 3 | C10: 12-15 | D10: — | E10: Your pick | F10: 8-9 | G10: 90 sec | H10: Lean torso forward slightly for a longer hamstring stretch. Squeeze 1 sec at full flexion, 3-sec lowering.
A11: Standing Calf Raise | B11: 3 | C11: 10-12 | D11: — | E11: Your pick | F11: 8-9 | G11: 90 sec | H11: Full stretch at the bottom for a 2-count, drive through the big toe, pause at the top. No bouncing.
A12: Cable Crunch | B12: 3 | C12: 12-15 | D12: — | E12: Your pick | F12: 8 | G12: 60-90 sec | H12: Flex the spine — ribs to hips, don't just bow at the waist. Strong abs = strong squat brace.
A14: THURSDAY — UPPER A: BENCH STRENGTH + BACK (target: ≤85 min)
A15: Exercise | B15: Set | C15: Target Reps | D15: %1RM | E15: Target Weight | F15: Target RPE | G15: Rest | H15: Coaching Cues / Special Instructions | I15: Actual Weight | J15: Actual Reps | K15: Actual RPE | L15: Set Notes (how it felt, bar speed, pump, tweaks)
A16: Competition Bench | B16: 1 | C16: 3 | D16: 80% | E16: =MROUND('Start Here'!$C$8*0.8,5) | F16: 8 | G16: 3-4 min | H16: Comp pause on every rep this day. Set your arch, pull the bar apart, tuck elbows ~45°, press back over your face. Leg drive on.
B17: 2 | C17: 3 | D17: 80% | E17: =MROUND('Start Here'!$C$8*0.8,5) | F17: 8 | G17: 3-4 min
B18: 3 | C18: 3 | D18: 80% | E18: =MROUND('Start Here'!$C$8*0.8,5) | F18: 8 | G18: 3-4 min
B19: 4 | C19: 3 | D19: 80% | E19: =MROUND('Start Here'!$C$8*0.8,5) | F19: 8 | G19: 3-4 min
A20: Weighted Pull-Up | B20: 4 | C20: 6-8 | D20: — | E20: Your pick | F20: 8 | G20: 2-3 min | H20: Add weight when you own 4x8 at bodyweight+. Dead hang start, drive elbows to hips, chest to bar. Lats build your bench arch and your V-taper.
A21: Seated DB Shoulder Press | B21: 3 | C21: 8-10 | D21: — | E21: Your pick | F21: 8 | G21: 2 min | H21: Slight back support, press up-and-in, stop just short of lockout to keep tension on delts. Start ~55-65s.
A22: Chest-Supported Row | B22: 3 | C22: 10-12 | D22: — | E22: Your pick | F22: 8 | G22: 90 sec | H22: Chest glued to pad — no cheating with body English. Pull to lower ribs, squeeze the shoulder blades for 1 sec.
A23: SUPERSET: EZ-Bar Curl + Overhead Cable Extension | B23: 3 | C23: 10-12 each | D23: — | E23: Your pick | F23: 8 | G23: 90 sec after pair | H23: Curls: elbows pinned, no swing. Overhead extensions: full stretch behind head — long-head triceps grow from the stretch. Alternate exercises, rest after both.
A24: Face Pull | B24: 3 | C24: 15-20 | D24: — | E24: Your pick | F24: 8 | G24: 60 sec | H24: Rope to forehead, thumbs back, external rotate at the end. Shoulder insurance — never skip these.
A26: SATURDAY — LOWER B: DEADLIFT + ATHLETIC LOWER (long session — take your time)
A27: Exercise | B27: Set | C27: Target Reps | D27: %1RM | E27: Target Weight | F27: Target RPE | G27: Rest | H27: Coaching Cues / Special Instructions | I27: Actual Weight | J27: Actual Reps | K27: Actual RPE | L27: Set Notes (how it felt, bar speed, pump, tweaks)
A28: Deadlift | B28: 1 | C28: 3 | D28: 80% | E28: =MROUND('Start Here'!$C$9*0.8,5) | F28: 8 | G28: 3-4 min | H28: Wedge hard, pull the slack out until the bar clicks, push the floor away. Hips and shoulders rise together. Reset every rep — no touch-and-go here.
B29: 2 | C29: 3 | D29: 80% | E29: =MROUND('Start Here'!$C$9*0.8,5) | F29: 8 | G29: 3-4 min
B30: 3 | C30: 3 | D30: 80% | E30: =MROUND('Start Here'!$C$9*0.8,5) | F30: 8 | G30: 3-4 min
A31: Paused Squat (2-ct) | B31: 1 | C31: 3 | D31: 70% | E31: =MROUND('Start Here'!$C$7*0.7,5) | F31: 8 | G31: 3-4 min | H31: 2-second dead-stop in the hole, stay braced and upright, no bounce. Builds bottom-position strength and quad size. Own the pause — don't rush it.
B32: 2 | C32: 3 | D32: 70% | E32: =MROUND('Start Here'!$C$7*0.7,5) | F32: 8 | G32: 3-4 min
B33: 3 | C33: 3 | D33: 70% | E33: =MROUND('Start Here'!$C$7*0.7,5) | F33: 8 | G33: 3-4 min
A34: Bulgarian Split Squat | B34: 3 | C34: 8-10 /leg | D34: — | E34: Your pick | F34: 8 | G34: 2 min | H34: Rear foot elevated, slight forward lean for glutes, upright for quads — pick your target. This is your athleticism builder: balance, single-leg strength, hip stability. Start with 40-50 lb DBs.
A35: Back Extension (glute bias) | B35: 3 | C35: 12-15 | D35: — | E35: Your pick | F35: 8-9 | G35: 90 sec | H35: Round upper back slightly, tuck chin, squeeze glutes to lift — don't hyperextend the spine. Hold a plate when 15 gets easy.
A36: Walking DB Lunge | B36: 2 | C36: 20 steps | D36: — | E36: Your pick | F36: 8 | G36: 2 min | H36: Long strides, soft knee touch, continuous walking. Brutal and athletic. Light DBs are plenty after everything else.
A37: Seated Calf Raise | B37: 4 | C37: 12-15 | D37: — | E37: Your pick | F37: 8-9 | G37: 60-90 sec | H37: Soleus focus. Slow 3-sec negative, deep stretch, pause at top.
A38: Hanging Leg Raise | B38: 3 | C38: 10-15 | D38: — | E38: Your pick | F38: 8 | G38: 90 sec | H38: Posterior pelvic tilt at the top — curl the pelvis up, don't just swing the legs. Bend knees if needed.
A40: SUNDAY — UPPER B: VOLUME BENCH + PUMP DAY (long session — chase the pump)
A41: Exercise | B41: Set | C41: Target Reps | D41: %1RM | E41: Target Weight | F41: Target RPE | G41: Rest | H41: Coaching Cues / Special Instructions | I41: Actual Weight | J41: Actual Reps | K41: Actual RPE | L41: Set Notes (how it felt, bar speed, pump, tweaks)
A42: Touch-and-Go Bench | B42: 1 | C42: 8 | D42: 70% | E42: =MROUND('Start Here'!$C$8*0.7,5) | F42: 8 | G42: 3-4 min | H42: Smooth touch, no bounce off the chest. Slight tuck, squeeze pecs hard at lockout each rep. This is a muscle set, not a strength test — chase the pec pump.
B43: 2 | C43: 8 | D43: 70% | E43: =MROUND('Start Here'!$C$8*0.7,5) | F43: 8 | G43: 3-4 min
...

Sheet Week 7
A1: FORGED 4-DAY POWERBUILDER — WEEK 7 | BLOCK 2: STRENGTH EXPRESSION
A2: TUESDAY — LOWER A: SQUAT STRENGTH + POSTERIOR CHAIN (target: ≤85 min)
A3: Exercise | B3: Set | C3: Target Reps | D3: %1RM | E3: Target Weight | F3: Target RPE | G3: Rest | H3: Coaching Cues / Special Instructions | I3: Actual Weight | J3: Actual Reps | K3: Actual RPE | L3: Set Notes (how it felt, bar speed, pump, tweaks)
A4: Competition Squat | B4: 1 | C4: 3 | D4: 82.5% | E4: =MROUND('Start Here'!$C$7*0.825,5) | F4: 8.5 | G4: 3-4 min | H4: Full comp setup every set: same walkout, same bracing. Big 360° breath, spread the floor, drive up through mid-foot. Treat every rep like a platform rep. Last set: optional AMRAP, stop at RPE 9. Log reps for new e1RM.
B5: 2 | C5: 3 | D5: 82.5% | E5: =MROUND('Start Here'!$C$7*0.825,5) | F5: 8.5 | G5: 3-4 min
B6: 3 | C6: 3 | D6: 82.5% | E6: =MROUND('Start Here'!$C$7*0.825,5) | F6: 8.5 | G6: 3-4 min
A7: Romanian Deadlift | B7: 3 | C7: 8-10 | D7: — | E7: Your pick | F7: 7-8 | G7: 2-3 min | H7: Soft knees, push hips back until hamstrings scream, bar drags the thighs. Start ~185-225 and add when all sets hit 10. Feel the stretch — that's the growth signal.
A8: Leg Press (feet low & narrow) | B8: 3 | C8: 10-12 | D8: — | E8: Your pick | F8: 8 | G8: 2 min | H8: Quad-bias stance. Full depth without butt tucking, 2-sec lowering. Drive knees over toes. Don't chase plates — chase the quad burn.
A9: Seated Leg Curl | B9: 3 | C9: 12-15 | D9: — | E9: Your pick | F9: 8-9 | G9: 90 sec | H9: Lean torso forward slightly for a longer hamstring stretch. Squeeze 1 sec at full flexion, 3-sec lowering.
A10: Standing Calf Raise | B10: 3 | C10: 10-12 | D10: — | E10: Your pick | F10: 8-9 | G10: 90 sec | H10: Full stretch at the bottom for a 2-count, drive through the big toe, pause at the top. No bouncing.
A11: Cable Crunch | B11: 3 | C11: 12-15 | D11: — | E11: Your pick | F11: 8 | G11: 60-90 sec | H11: Flex the spine — ribs to hips, don't just bow at the waist. Strong abs = strong squat brace.
A13: THURSDAY — UPPER A: BENCH STRENGTH + BACK (target: ≤85 min)
A14: Exercise | B14: Set | C14: Target Reps | D14: %1RM | E14: Target Weight | F14: Target RPE | G14: Rest | H14: Coaching Cues / Special Instructions | I14: Actual Weight | J14: Actual Reps | K14: Actual RPE | L14: Set Notes (how it felt, bar speed, pump, tweaks)
A15: Competition Bench | B15: 1 | C15: 3 | D15: 82.5% | E15: =MROUND('Start Here'!$C$8*0.825,5) | F15: 8.5 | G15: 3-4 min | H15: Comp pause on every rep this day. Set your arch, pull the bar apart, tuck elbows ~45°, press back over your face. Leg drive on. Last set: optional AMRAP, stop at RPE 9. Log reps for new e1RM.
B16: 2 | C16: 3 | D16: 82.5% | E16: =MROUND('Start Here'!$C$8*0.825,5) | F16: 8.5 | G16: 3-4 min
B17: 3 | C17: 3 | D17: 82.5% | E17: =MROUND('Start Here'!$C$8*0.825,5) | F17: 8.5 | G17: 3-4 min
A18: Weighted Pull-Up | B18: 4 | C18: 6-8 | D18: — | E18: Your pick | F18: 8 | G18: 2-3 min | H18: Add weight when you own 4x8 at bodyweight+. Dead hang start, drive elbows to hips, chest to bar. Lats build your bench arch and your V-taper.
A19: Seated DB Shoulder Press | B19: 3 | C19: 8-10 | D19: — | E19: Your pick | F19: 8 | G19: 2 min | H19: Slight back support, press up-and-in, stop just short of lockout to keep tension on delts. Start ~55-65s.
A20: Chest-Supported Row | B20: 3 | C20: 10-12 | D20: — | E20: Your pick | F20: 8 | G20: 90 sec | H20: Chest glued to pad — no cheating with body English. Pull to lower ribs, squeeze the shoulder blades for 1 sec.
A21: SUPERSET: EZ-Bar Curl + Overhead Cable Extension | B21: 3 | C21: 10-12 each | D21: — | E21: Your pick | F21: 8 | G21: 90 sec after pair | H21: Curls: elbows pinned, no swing. Overhead extensions: full stretch behind head — long-head triceps grow from the stretch. Alternate exercises, rest after both.
A22: Face Pull | B22: 3 | C22: 15-20 | D22: — | E22: Your pick | F22: 8 | G22: 60 sec | H22: Rope to forehead, thumbs back, external rotate at the end. Shoulder insurance — never skip these.
A24: SATURDAY — LOWER B: DEADLIFT + ATHLETIC LOWER (long session — take your time)
A25: Exercise | B25: Set | C25: Target Reps | D25: %1RM | E25: Target Weight | F25: Target RPE | G25: Rest | H25: Coaching Cues / Special Instructions | I25: Actual Weight | J25: Actual Reps | K25: Actual RPE | L25: Set Notes (how it felt, bar speed, pump, tweaks)
A26: Deadlift | B26: 1 | C26: 2 | D26: 82.5% | E26: =MROUND('Start Here'!$C$9*0.825,5) | F26: 8.5 | G26: 3-4 min | H26: Wedge hard, pull the slack out until the bar clicks, push the floor away. Hips and shoulders rise together. Reset every rep — no touch-and-go here. Then: optional heavy single @ 87.5% (~RPE 8.5). No grinders.
B27: 2 | C27: 2 | D27: 82.5% | E27: =MROUND('Start Here'!$C$9*0.825,5) | F27: 8.5 | G27: 3-4 min
A28: Paused Squat (2-ct) | B28: 1 | C28: 3 | D28: 72.5% | E28: =MROUND('Start Here'!$C$7*0.725,5) | F28: 8 | G28: 3-4 min | H28: 2-second dead-stop in the hole, stay braced and upright, no bounce. Builds bottom-position strength and quad size. Own the pause — don't rush it.
B29: 2 | C29: 3 | D29: 72.5% | E29: =MROUND('Start Here'!$C$7*0.725,5) | F29: 8 | G29: 3-4 min
B30: 3 | C30: 3 | D30: 72.5% | E30: =MROUND('Start Here'!$C$7*0.725,5) | F30: 8 | G30: 3-4 min
A31: Bulgarian Split Squat | B31: 3 | C31: 8-10 /leg | D31: — | E31: Your pick | F31: 8 | G31: 2 min | H31: Rear foot elevated, slight forward lean for glutes, upright for quads — pick your target. This is your athleticism builder: balance, single-leg strength, hip stability. Start with 40-50 lb DBs.
A32: Back Extension (glute bias) | B32: 3 | C32: 12-15 | D32: — | E32: Your pick | F32: 8-9 | G32: 90 sec | H32: Round upper back slightly, tuck chin, squeeze glutes to lift — don't hyperextend the spine. Hold a plate when 15 gets easy.
A33: Walking DB Lunge | B33: 2 | C33: 20 steps | D33: — | E33: Your pick | F33: 8 | G33: 2 min | H33: Long strides, soft knee touch, continuous walking. Brutal and athletic. Light DBs are plenty after everything else.
A34: Seated Calf Raise | B34: 4 | C34: 12-15 | D34: — | E34: Your pick | F34: 8-9 | G34: 60-90 sec | H34: Soleus focus. Slow 3-sec negative, deep stretch, pause at top.
A35: Hanging Leg Raise | B35: 3 | C35: 10-15 | D35: — | E35: Your pick | F35: 8 | G35: 90 sec | H35: Posterior pelvic tilt at the top — curl the pelvis up, don't just swing the legs. Bend knees if needed.
A37: SUNDAY — UPPER B: VOLUME BENCH + PUMP DAY (long session — chase the pump)
A38: Exercise | B38: Set | C38: Target Reps | D38: %1RM | E38: Target Weight | F38: Target RPE | G38: Rest | H38: Coaching Cues / Special Instructions | I38: Actual Weight | J38: Actual Reps | K38: Actual RPE | L38: Set Notes (how it felt, bar speed, pump, tweaks)
A39: Touch-and-Go Bench | B39: 1 | C39: 8 | D39: 72.5% | E39: =MROUND('Start Here'!$C$8*0.725,5) | F39: 8 | G39: 3-4 min | H39: Smooth touch, no bounce off the chest. Slight tuck, squeeze pecs hard at lockout each rep. This is a muscle set, not a strength test — chase the pec pump.
B40: 2 | C40: 8 | D40: 72.5% | E40: =MROUND('Start Here'!$C$8*0.725,5) | F40: 8 | G40: 3-4 min
B41: 3 | C41: 8 | D41: 72.5% | E41: =MROUND('Start Here'!$C$8*0.725,5) | F41: 8 | G41: 3-4 min
B42: 4 | C42: 8 | D42: 72.5% | E42: =MROUND('Start Here'!$C$8*0.725,5) | F42: 8 | G42: 3-4 min
A43: Incline DB Press (30°) | B43: 3 | C43: 10-12 | D43: — | E43: Your pick | F43: 8 | G43: 2 min | H43: Deep stretch at the bottom, press up-and-in, squeeze upper pecs at top. Don't touch the DBs together hard — keep tension. Start ~75-85s.
...

Sheet Week 8
A1: FORGED 4-DAY POWERBUILDER — WEEK 8 | BLOCK 2: STRENGTH EXPRESSION • DELOAD WEEK — recover, move fast, leave feeling fresh
A2: TUESDAY — LOWER A: SQUAT STRENGTH + POSTERIOR CHAIN (target: ≤85 min)
A3: Exercise | B3: Set | C3: Target Reps | D3: %1RM | E3: Target Weight | F3: Target RPE | G3: Rest | H3: Coaching Cues / Special Instructions | I3: Actual Weight | J3: Actual Reps | K3: Actual RPE | L3: Set Notes (how it felt, bar speed, pump, tweaks)
A4: Competition Squat | B4: 1 | C4: 3 | D4: 65% | E4: =MROUND('Start Here'!$C$7*0.65,5) | F4: ≤6 | G4: 3-4 min | H4: Full comp setup every set: same walkout, same bracing. Big 360° breath, spread the floor, drive up through mid-foot. Treat every rep like a platform rep. DELOAD — move fast, leave the gym feeling fresh.
B5: 2 | C5: 3 | D5: 65% | E5: =MROUND('Start Here'!$C$7*0.65,5) | F5: ≤6 | G5: 3-4 min
B6: 3 | C6: 3 | D6: 65% | E6: =MROUND('Start Here'!$C$7*0.65,5) | F6: ≤6 | G6: 3-4 min
A7: Romanian Deadlift | B7: 2 | C7: 8-10 | D7: — | E7: Your pick | F7: 6-7 | G7: 2-3 min | H7: DELOAD: 2 easy sets, stay 3-4 reps from failure. Soft knees, push hips back until hamstrings scream, bar drags the thighs. Start ~185-225 and add when all sets hit 10. Feel the stretch — that's the growth signal.
A8: Leg Press (feet low & narrow) | B8: 2 | C8: 10-12 | D8: — | E8: Your pick | F8: 6-7 | G8: 2 min | H8: DELOAD: 2 easy sets, stay 3-4 reps from failure. Quad-bias stance. Full depth without butt tucking, 2-sec lowering. Drive knees over toes. Don't chase plates — chase the quad burn.
A9: Seated Leg Curl | B9: 2 | C9: 12-15 | D9: — | E9: Your pick | F9: 6-7 | G9: 90 sec | H9: DELOAD: 2 easy sets, stay 3-4 reps from failure. Lean torso forward slightly for a longer hamstring stretch. Squeeze 1 sec at full flexion, 3-sec lowering.
A10: Standing Calf Raise | B10: 2 | C10: 10-12 | D10: — | E10: Your pick | F10: 6-7 | G10: 90 sec | H10: DELOAD: 2 easy sets, stay 3-4 reps from failure. Full stretch at the bottom for a 2-count, drive through the big toe, pause at the top. No bouncing.
A11: Cable Crunch | B11: 2 | C11: 12-15 | D11: — | E11: Your pick | F11: 6-7 | G11: 60-90 sec | H11: DELOAD: 2 easy sets, stay 3-4 reps from failure. Flex the spine — ribs to hips, don't just bow at the waist. Strong abs = strong squat brace.
A13: THURSDAY — UPPER A: BENCH STRENGTH + BACK (target: ≤85 min)
A14: Exercise | B14: Set | C14: Target Reps | D14: %1RM | E14: Target Weight | F14: Target RPE | G14: Rest | H14: Coaching Cues / Special Instructions | I14: Actual Weight | J14: Actual Reps | K14: Actual RPE | L14: Set Notes (how it felt, bar speed, pump, tweaks)
A15: Competition Bench | B15: 1 | C15: 3 | D15: 65% | E15: =MROUND('Start Here'!$C$8*0.65,5) | F15: ≤6 | G15: 3-4 min | H15: Comp pause on every rep this day. Set your arch, pull the bar apart, tuck elbows ~45°, press back over your face. Leg drive on. DELOAD.
B16: 2 | C16: 3 | D16: 65% | E16: =MROUND('Start Here'!$C$8*0.65,5) | F16: ≤6 | G16: 3-4 min
B17: 3 | C17: 3 | D17: 65% | E17: =MROUND('Start Here'!$C$8*0.65,5) | F17: ≤6 | G17: 3-4 min
A18: Weighted Pull-Up | B18: 3 | C18: 6-8 | D18: — | E18: Your pick | F18: 6-7 | G18: 2-3 min | H18: DELOAD: 3 easy sets, stay 3-4 reps from failure. Add weight when you own 4x8 at bodyweight+. Dead hang start, drive elbows to hips, chest to bar. Lats build your bench arch and your V-taper.
A19: Seated DB Shoulder Press | B19: 2 | C19: 8-10 | D19: — | E19: Your pick | F19: 6-7 | G19: 2 min | H19: DELOAD: 2 easy sets, stay 3-4 reps from failure. Slight back support, press up-and-in, stop just short of lockout to keep tension on delts. Start ~55-65s.
A20: Chest-Supported Row | B20: 2 | C20: 10-12 | D20: — | E20: Your pick | F20: 6-7 | G20: 90 sec | H20: DELOAD: 2 easy sets, stay 3-4 reps from failure. Chest glued to pad — no cheating with body English. Pull to lower ribs, squeeze the shoulder blades for 1 sec.
A21: SUPERSET: EZ-Bar Curl + Overhead Cable Extension | B21: 2 | C21: 10-12 each | D21: — | E21: Your pick | F21: 6-7 | G21: 90 sec after pair | H21: DELOAD: 2 easy sets, stay 3-4 reps from failure. Curls: elbows pinned, no swing. Overhead extensions: full stretch behind head — long-head triceps grow from the stretch. Alternate exercises, rest after both.
A22: Face Pull | B22: 2 | C22: 15-20 | D22: — | E22: Your pick | F22: 6-7 | G22: 60 sec | H22: DELOAD: 2 easy sets, stay 3-4 reps from failure. Rope to forehead, thumbs back, external rotate at the end. Shoulder insurance — never skip these.
A24: SATURDAY — LOWER B: DEADLIFT + ATHLETIC LOWER (long session — take your time)
A25: Exercise | B25: Set | C25: Target Reps | D25: %1RM | E25: Target Weight | F25: Target RPE | G25: Rest | H25: Coaching Cues / Special Instructions | I25: Actual Weight | J25: Actual Reps | K25: Actual RPE | L25: Set Notes (how it felt, bar speed, pump, tweaks)
A26: Deadlift | B26: 1 | C26: 3 | D26: 65% | E26: =MROUND('Start Here'!$C$9*0.65,5) | F26: ≤6 | G26: 3-4 min | H26: Wedge hard, pull the slack out until the bar clicks, push the floor away. Hips and shoulders rise together. Reset every rep — no touch-and-go here. DELOAD.
B27: 2 | C27: 3 | D27: 65% | E27: =MROUND('Start Here'!$C$9*0.65,5) | F27: ≤6 | G27: 3-4 min
